[2024-11-16T16:27:10.096+0000] {local_task_job_runner.py:123} INFO - ::group::Pre task execution logs
[2024-11-16T16:27:10.154+0000] {taskinstance.py:2612} INFO - Dependencies all met for dep_context=non-requeueable deps ti=<TaskInstance: add_data_API.run_API_news manual__2024-11-16T16:25:48.867823+00:00 [queued]>
[2024-11-16T16:27:10.182+0000] {taskinstance.py:2612} INFO - Dependencies all met for dep_context=requeueable deps ti=<TaskInstance: add_data_API.run_API_news manual__2024-11-16T16:25:48.867823+00:00 [queued]>
[2024-11-16T16:27:10.185+0000] {taskinstance.py:2865} INFO - Starting attempt 1 of 2
[2024-11-16T16:27:10.233+0000] {taskinstance.py:2888} INFO - Executing <Task(BashOperator): run_API_news> on 2024-11-16 16:25:48.867823+00:00
[2024-11-16T16:27:10.278+0000] {warnings.py:112} WARNING - /home/***/.local/lib/python3.12/site-packages/***/task/task_runner/standard_task_runner.py:70: DeprecationWarning: This process (pid=861) is multi-threaded, use of fork() may lead to deadlocks in the child.
  pid = os.fork()

[2024-11-16T16:27:10.283+0000] {standard_task_runner.py:72} INFO - Started process 863 to run task
[2024-11-16T16:27:10.284+0000] {standard_task_runner.py:104} INFO - Running: ['***', 'tasks', 'run', 'add_data_API', 'run_API_news', 'manual__2024-11-16T16:25:48.867823+00:00', '--job-id', '686', '--raw', '--subdir', 'DAGS_FOLDER/insert_data.py', '--cfg-path', '/tmp/tmpyuzlyoxe']
[2024-11-16T16:27:10.292+0000] {standard_task_runner.py:105} INFO - Job 686: Subtask run_API_news
[2024-11-16T16:27:10.461+0000] {task_command.py:467} INFO - Running <TaskInstance: add_data_API.run_API_news manual__2024-11-16T16:25:48.867823+00:00 [running]> on host c967fb0415e1
[2024-11-16T16:27:10.968+0000] {taskinstance.py:3131} INFO - Exporting env vars: AIRFLOW_CTX_DAG_OWNER='***' AIRFLOW_CTX_DAG_ID='add_data_API' AIRFLOW_CTX_TASK_ID='run_API_news' AIRFLOW_CTX_EXECUTION_DATE='2024-11-16T16:25:48.867823+00:00' AIRFLOW_CTX_TRY_NUMBER='1' AIRFLOW_CTX_DAG_RUN_ID='manual__2024-11-16T16:25:48.867823+00:00'
[2024-11-16T16:27:10.979+0000] {logging_mixin.py:190} INFO - Task instance is in running state
[2024-11-16T16:27:10.981+0000] {logging_mixin.py:190} INFO -  Previous state of the Task instance: queued
[2024-11-16T16:27:10.983+0000] {logging_mixin.py:190} INFO - Current task name:run_API_news state:running start_date:2024-11-16 16:27:10.156500+00:00
[2024-11-16T16:27:10.985+0000] {logging_mixin.py:190} INFO - Dag name:add_data_API and current dag run status:running
[2024-11-16T16:27:10.988+0000] {taskinstance.py:731} INFO - ::endgroup::
[2024-11-16T16:27:11.070+0000] {subprocess.py:63} INFO - Tmp dir root location: /tmp
[2024-11-16T16:27:11.201+0000] {subprocess.py:75} INFO - Running command: ['/usr/bin/bash', '-c', 'python C:/Users/33672/OneDrive/Documents/GitHub/Projet_EDD/script/getAPI.py']
[2024-11-16T16:27:11.324+0000] {subprocess.py:86} INFO - Output:
[2024-11-16T16:27:11.889+0000] {subprocess.py:93} INFO - python: can't open file '/tmp/***tmp4ffskhku/C:/Users/33672/OneDrive/Documents/GitHub/Projet_EDD/script/getAPI.py': [Errno 2] No such file or directory
[2024-11-16T16:27:11.902+0000] {subprocess.py:97} INFO - Command exited with return code 2
[2024-11-16T16:27:12.025+0000] {taskinstance.py:3310} ERROR - Task failed with exception
Traceback (most recent call last):
  File "/home/airflow/.local/lib/python3.12/site-packages/airflow/models/taskinstance.py", line 767, in _execute_task
    result = _execute_callable(context=context, **execute_callable_kwargs)
             ^^^^^^^^^^^^^^^^^^^^^^^^^^^^^^^^^^^^^^^^^^^^^^^^^^^^^^^^^^^^^
  File "/home/airflow/.local/lib/python3.12/site-packages/airflow/models/taskinstance.py", line 733, in _execute_callable
    return ExecutionCallableRunner(
           ^^^^^^^^^^^^^^^^^^^^^^^^
  File "/home/airflow/.local/lib/python3.12/site-packages/airflow/utils/operator_helpers.py", line 252, in run
    return self.func(*args, **kwargs)
           ^^^^^^^^^^^^^^^^^^^^^^^^^^
  File "/home/airflow/.local/lib/python3.12/site-packages/airflow/models/baseoperator.py", line 406, in wrapper
    return func(self, *args, **kwargs)
           ^^^^^^^^^^^^^^^^^^^^^^^^^^^
  File "/home/airflow/.local/lib/python3.12/site-packages/airflow/operators/bash.py", line 249, in execute
    raise AirflowException(
airflow.exceptions.AirflowException: Bash command failed. The command returned a non-zero exit code 2.
[2024-11-16T16:27:12.086+0000] {logging_mixin.py:190} INFO - Task instance in failure state
[2024-11-16T16:27:12.088+0000] {logging_mixin.py:190} INFO - Task start:2024-11-16 16:27:10.156500+00:00 end:2024-11-16 16:27:12.084447+00:00 duration:1.927947
[2024-11-16T16:27:12.091+0000] {logging_mixin.py:190} INFO - Task:<Task(BashOperator): run_API_news> dag:<DAG: add_data_API> dagrun:<DagRun add_data_API @ 2024-11-16 16:25:48.867823+00:00: manual__2024-11-16T16:25:48.867823+00:00, state:running, queued_at: 2024-11-16 16:25:49.353344+00:00. externally triggered: True>
[2024-11-16T16:27:12.093+0000] {logging_mixin.py:190} INFO - Failure caused by Bash command failed. The command returned a non-zero exit code 2.
[2024-11-16T16:27:12.095+0000] {taskinstance.py:1225} INFO - Marking task as UP_FOR_RETRY. dag_id=add_data_API, task_id=run_API_news, run_id=manual__2024-11-16T16:25:48.867823+00:00, execution_date=20241116T162548, start_date=20241116T162710, end_date=20241116T162712
[2024-11-16T16:27:12.211+0000] {taskinstance.py:340} INFO - ::group::Post task execution logs
[2024-11-16T16:27:12.215+0000] {standard_task_runner.py:124} ERROR - Failed to execute job 686 for task run_API_news (Bash command failed. The command returned a non-zero exit code 2.; 863)
Traceback (most recent call last):
  File "/home/airflow/.local/lib/python3.12/site-packages/airflow/task/task_runner/standard_task_runner.py", line 117, in _start_by_fork
    ret = args.func(args, dag=self.dag)
          ^^^^^^^^^^^^^^^^^^^^^^^^^^^^^
  File "/home/airflow/.local/lib/python3.12/site-packages/airflow/cli/cli_config.py", line 49, in command
    return func(*args, **kwargs)
           ^^^^^^^^^^^^^^^^^^^^^
  File "/home/airflow/.local/lib/python3.12/site-packages/airflow/utils/cli.py", line 115, in wrapper
    return f(*args, **kwargs)
           ^^^^^^^^^^^^^^^^^^
  File "/home/airflow/.local/lib/python3.12/site-packages/airflow/cli/commands/task_command.py", line 483, in task_run
    task_return_code = _run_task_by_selected_method(args, _dag, ti)
                       ^^^^^^^^^^^^^^^^^^^^^^^^^^^^^^^^^^^^^^^^^^^^
  File "/home/airflow/.local/lib/python3.12/site-packages/airflow/cli/commands/task_command.py", line 256, in _run_task_by_selected_method
    return _run_raw_task(args, ti)
           ^^^^^^^^^^^^^^^^^^^^^^^
  File "/home/airflow/.local/lib/python3.12/site-packages/airflow/cli/commands/task_command.py", line 341, in _run_raw_task
    return ti._run_raw_task(
           ^^^^^^^^^^^^^^^^^
  File "/home/airflow/.local/lib/python3.12/site-packages/airflow/utils/session.py", line 97, in wrapper
    return func(*args, session=session, **kwargs)
           ^^^^^^^^^^^^^^^^^^^^^^^^^^^^^^^^^^^^^^
  File "/home/airflow/.local/lib/python3.12/site-packages/airflow/models/taskinstance.py", line 3004, in _run_raw_task
    return _run_raw_task(
           ^^^^^^^^^^^^^^
  File "/home/airflow/.local/lib/python3.12/site-packages/airflow/models/taskinstance.py", line 273, in _run_raw_task
    TaskInstance._execute_task_with_callbacks(
  File "/home/airflow/.local/lib/python3.12/site-packages/airflow/models/taskinstance.py", line 3158, in _execute_task_with_callbacks
    result = self._execute_task(context, task_orig)
             ^^^^^^^^^^^^^^^^^^^^^^^^^^^^^^^^^^^^^^
  File "/home/airflow/.local/lib/python3.12/site-packages/airflow/models/taskinstance.py", line 3182, in _execute_task
    return _execute_task(self, context, task_orig)
           ^^^^^^^^^^^^^^^^^^^^^^^^^^^^^^^^^^^^^^^
  File "/home/airflow/.local/lib/python3.12/site-packages/airflow/models/taskinstance.py", line 767, in _execute_task
    result = _execute_callable(context=context, **execute_callable_kwargs)
             ^^^^^^^^^^^^^^^^^^^^^^^^^^^^^^^^^^^^^^^^^^^^^^^^^^^^^^^^^^^^^
  File "/home/airflow/.local/lib/python3.12/site-packages/airflow/models/taskinstance.py", line 733, in _execute_callable
    return ExecutionCallableRunner(
           ^^^^^^^^^^^^^^^^^^^^^^^^
  File "/home/airflow/.local/lib/python3.12/site-packages/airflow/utils/operator_helpers.py", line 252, in run
    return self.func(*args, **kwargs)
           ^^^^^^^^^^^^^^^^^^^^^^^^^^
  File "/home/airflow/.local/lib/python3.12/site-packages/airflow/models/baseoperator.py", line 406, in wrapper
    return func(self, *args, **kwargs)
           ^^^^^^^^^^^^^^^^^^^^^^^^^^^
  File "/home/airflow/.local/lib/python3.12/site-packages/airflow/operators/bash.py", line 249, in execute
    raise AirflowException(
airflow.exceptions.AirflowException: Bash command failed. The command returned a non-zero exit code 2.
[2024-11-16T16:27:12.327+0000] {local_task_job_runner.py:266} INFO - Task exited with return code 1
[2024-11-16T16:27:12.505+0000] {taskinstance.py:3900} INFO - 0 downstream tasks scheduled from follow-on schedule check
[2024-11-16T16:27:12.533+0000] {local_task_job_runner.py:245} INFO - ::endgroup::
